try {
    console.log(a+b)
}
catch(err) {
    console.log(err)
    console.log('there was a error')
    console.log('the error was saved in the error log')
}
 console.log('my program does not stop')